Workbook

Sheet 읽는 법
A1: 이 표를 읽는 법
A2: 1. 「수출용 도매 가격」은 원료가 나라와 나라 사이에서 대량으로 거래될 때의 가격입니다. 예) 1,000kg 당 7,558 위안 = 원료 1톤을 7,558위안에 사고판다는 뜻입니다.
A3: 2. 「제품 1단위 생산에 필요한 원료 비용」 = 제품 1단위에 드는 원료 양(g) × 1kg 당 가격(원) ÷ 1,000. 계산 과정은 「계산 근거」 시트에 있습니다.
A4: 3. 제품 1단위는 부가가치 학습자료와 같습니다 : 립밤 1개, 사인펜 1상자(12자루), 운동화 1켤레, 후드 집업 1벌, 무선 이어폰 1세트, 쿠키 1봉(180g).
A5: 4. 노란 줄(제품별 합계)은 부가가치 학습자료 「원료」 단계 금액의 근거입니다 : 립밤 60원, 사인펜 120원, 운동화 1,000원, 후드 집업 1,500원, 무선 이어폰 300원, 쿠키 560원.
A6: 5. 원유 줄은 플라스틱 수지(PP·ABS·PC) 가격에 이미 원유 값이 들어 있어 합계에서 뺐습니다. 원료가 어디서 시작되는지 보여 주려고 남겨 두었습니다.
A7: 6. 8월 1일은 토요일이라 직전 거래일 7월 31일(금) 가격을 쓰고, 그날 가격이 공개되지 않은 원료는 가장 가까운 날짜나 7월 평균 가격을 썼습니다. 비고 열의 「기준」을 보세요.
A8: 7/31 시세 · 7월 평균 · 7월 근접일 · 대용 지표(비슷한 원료 가격으로 대신함) · 참고 목록가(판매 목록, 2026-10-16 조회) · 미확인
A9: 7. 파란 글씨(가격, 원료 양, 환율)를 바꾸면 원료 비용과 합계가 자동으로 다시 계산됩니다.

Sheet 원료 가격
A1: 라벨 원료의 수출용 도매 가격과 제품 1단위의 원료 비용 — 2026년 8월 1일 기준
A2: 제품 1단위 = 립밤 1개 · 사인펜 1상자(12자루) · 운동화 1켤레 · 후드 집업 1벌 · 무선 이어폰 1세트 · 쿠키 1봉(180g). 부가가치 학습자료의 「원료」 단계 금액과 같은 기준입니다.
A4: 번호 | B4: 제품 | C4: 라벨표시 산지 | D4: 수출용 도매 가격 | E4: 제품 1단위 생산에 필요한 원료 비용 | F4: 비용 추정 근거 | G4: 출처 | H4: 통화코드 | I4: 비고
A5: 1 | B5: 립밤 1개 · 시어버터 (35%) | C5: 부르키나파소 | D5: 7.24 | E5: =IF('계산 근거'!J2="","",'계산 근거'!J2) -> 16.237872 | F5: 원료 양 1.575g (립밤 4.5g × 시어버터 35%) × 1kg 당 가격(원) ÷ 1,000 | G5: Accio 시어버터 도매 목록 | H5: USD | I5: 기준 : 참고 목록가 (2026-10-16 조회). 시세 지표 : 비정제 시어버터 도매 목록가 (중간값). 목록가 범위 5.58~8.90 USD/kg의 중간값. 날짜 없는 판매 목록이라 8월 1일 시세가 아님
A6: 2 | B6: 립밤 1개 · 밀납 (25%) | C6: 중국 | D6: 9.6 | E6: =IF('계산 근거'!J3="","",'계산 근거'!J3) -> 15.3792 | F6: 원료 양 1.125g (립밤 4.5g × 밀납 25%) × 1kg 당 가격(원) ÷ 1,000 | G6: Bulk Natural Oils: 밀납(황색 과립) | H6: USD | I6: 기준 : 참고 목록가 (2026-10-16 조회). 시세 지표 : 황색 밀납 과립, 중국산 도매 목록가. 12.5kg 120달러. 미국산은 11.60 USD/kg
A7: 3 | B7: 립밤 1개 · 코코넛오일 (15%) | C7: 필리핀 | D7: 1924 | E7: =IF('계산 근거'!J4="","",'계산 근거'!J4) -> 1.8493488 | F7: 원료 양 0.675g (립밤 4.5g × 코코넛오일 15%) × 1kg 당 가격(원) ÷ 1,000 | G7: 세계은행 Pink Sheet (2026년 8월 4일 발행, 7월 평균) | H7: USD | I7: 기준 : 7월 평균 (2026년 7월 평균). 시세 지표 : 코코넛오일 (세계은행)
A8: 4 | B8: 립밤 1개 · 해바라기씨오일 (12%) | C8: 우크라이나 | D8: 1377.5 | E8: =IF('계산 근거'!J5="","",'계산 근거'!J5) -> 1.0592424 | F8: 원료 양 0.54g (립밤 4.5g × 해바라기씨오일 12%) × 1kg 당 가격(원) ÷ 1,000 | G8: Commodity-Board: 우크라이나 해바라기 시장 | H8: USD | I8: 기준 : 7월 근접일 (2026-07-16까지 자료). 시세 지표 : 우크라이나 해바라기유 FOB (중간값). 범위 1,370~1,385 USD/t의 중간값. 기사 스스로 "호가"라고 밝힘
A9: 5 | B9: 립밤 1개 · 호호바씨오일 (8%) | C9: 아르헨티나 | D9: 14.75 | E9: =IF('계산 근거'!J6="","",'계산 근거'!J6) -> 7.56144 | F9: 원료 양 0.36g (립밤 4.5g × 호호바씨오일 8%) × 1kg 당 가격(원) ÷ 1,000 | G9: Bulk Natural Oils: 호호바오일(골든) | H9: USD | I9: 기준 : 참고 목록가 (2026-10-16 조회). 시세 지표 : 골든 호호바오일 도매 목록가. 17kg 통 250.75달러
A10: 6 | B10: 립밤 1개 · 카나우바왁스 (4.5%) | C10: 브라질 | D10: 16.4 | E10: =IF('계산 근거'!J7="","",'계산 근거'!J7) -> 4.729104 | F10: 원료 양 0.2025g (립밤 4.5g × 카나우바왁스 4.5%) × 1kg 당 가격(원) ÷ 1,000 | G10: Bulk Natural Oils: 카나우바왁스 T1 | H10: USD | I10: 기준 : 참고 목록가 (2026-10-16 조회). 시세 지표 : 카나우바왁스 T1 도매 목록가. 25kg 410달러
A11: 7 | B11: 립밤 1개 · 토코페롤 (0.5%) | C11: 프랑스 | E11: =IF('계산 근거'!J8="","",'계산 근거'!J8) | F11: 원료 양 0.0225g (립밤 4.5g × 토코페롤 0.5%) × 1kg 당 가격(원) ÷ 1,000 | G11: — | H11: — | I11: 기준 : 미확인. 공개된 시세를 찾지 못함
A12: 8 | B12: 립밤 1개 · 용기 : 폴리프로필렌(PP) 수지 | C12: 대한민국(울산) | D12: 8973.33 | E12: =IF('계산 근거'!J9="","",'계산 근거'!J9) -> 9.4650542 | F12: 원료 양 5g (립밤 용기 무게 약 5g으로 가정) × 1kg 당 가격(원) ÷ 1,000 | G12: SunSirs: China PP Prices Consolidate After July Rise | H12: CNY | I12: 기준 : 7/31 시세 (2026-07-31). 시세 지표 : PP 중국 현물 기준가. 라벨은 한국산 수지이나 공개 시세는 중국 기준가
A13: 9 | B13: 립밤 1개 · 용기 : 수지 원료(원유) | C13: 사우디아라비아 | D13: 96.95 | E13: =IF('계산 근거'!J10="","",'계산 근거'!J10) -> 10.121466 | F13: 원료 양 10g (플라스틱 1kg에 원유 약 2kg이 든다고 가정 → 용기 5g × 2) × 1kg 당 가격(원) ÷ 1,000 · 수지 가격에 이미 들어 있어 합계에서 제외 | G13: 미국 에너지정보청(EIA) Brent 현물 일별 | H13: USD | I13: 기준 : 7/31 시세 (2026-07-31). 시세 지표 : Brent 원유 현물 (EIA). 1배럴 ≈ 136.4kg로 환산(가정). 같은 날 Brent 선물 정산가는 90.12 USD
B14: 립밤 1개 원료 비용 합계 (조사값) | E14: =SUM(E5,E6,E7,E8,E9,E10,E11,E12) -> 56.281261 | F14: 부가가치 학습자료의 원료 단계 금액 : 60원 | I14: 조사값 합계에 원료 운송비를 더해 약 60원
A15: 10 | B15: 사인펜 1상자(12자루) · 몸체·캡 : PP 수지 | C15: 대한민국(여수) | D15: 8973.33 | E15: =IF('계산 근거'!J11="","",'계산 근거'!J11) -> 113.58065 | F15: 원료 양 60g (1자루 몸체·캡 약 5g × 12자루) × 1kg 당 가격(원) ÷ 1,000 | G15: SunSirs: China PP Prices Consolidate After July Rise | H15: CNY | I15: 기준 : 7/31 시세 (2026-07-31). 시세 지표 : PP 중국 현물 기준가
A16: 11 | B16: 사인펜 1상자(12자루) · PP 원료 : 원유 | C16: 쿠웨이트 | D16: 96.95 | E16: =IF('계산 근거'!J12="","",'계산 근거'!J12) -> 121.4576 | F16: 원료 양 120g (플라스틱 1kg에 원유 약 2kg 가정 → 60g × 2) × 1kg 당 가격(원) ÷ 1,000 · 수지 가격에 이미 들어 있어 합계에서 제외 | G16: 미국 에너지정보청(EIA) Brent 현물 일별 | H16: USD | I16: 기준 : 7/31 시세 (2026-07-31). 시세 지표 : Brent 원유 현물 (EIA). 쿠웨이트 원유 대신 국제 기준 유종인 Brent 사용
A17: 12 | B17: 사인펜 1상자(12자루) · 펜촉 : 폴리에스터 섬유 | C17: 중국(장쑤성) | D17: 7558 | E17: =IF('계산 근거'!J13="","",'계산 근거'!J13) -> 1.9133199 | F17: 원료 양 1.2g (펜촉 1개 약 0.1g × 12자루) × 1kg 당 가격(원) ÷ 1,000 | G17: SunSirs: Polyester Staple Fiber Prices Fluctuated Upward in July | H17: CNY | I17: 기준 : 7월 근접일 (2026-07-30). 시세 지표 : 폴리에스터 단섬유(PSF) 중국
A18: 13 | B18: 사인펜 1상자(12자루) · 잉크 : 카본블랙 안료 | C18: 일본 | E18: =IF('계산 근거'!J14="","",'계산 근거'!J14) | F18: 원료 양 0.9g (잉크 약 1.5g 중 카본블랙 5% × 12자루) × 1kg 당 가격(원) ÷ 1,000 | G18: — | H18: — | I18: 기준 : 미확인. 7월 시세 미확인. 참고: 중국 N220 등급 8,320 CNY/t (2026-08-05, SunSirs 35048)
B19: 사인펜 1상자(12자루) 원료 비용 합계 (조사값) | E19: =SUM(E15,E17,E18) -> 115.49397 | F19: 부가가치 학습자료의 원료 단계 금액 : 120원 | I19: 조사값 합계에 가격을 찾지 못한 잉크 재료(카본블랙 등) 약 4원을 더해 약 120원
A20: 14 | B20: 운동화 1켤레 · 갑피 : 폴리에스터 원사 | C20: 중국 | D20: 8800 | E20: =IF('계산 근거'!J15="","",'계산 근거'!J15) -> 111.38671 | F20: 원료 양 60g (한 켤레 갑피 메시 약 60g으로 가정) × 1kg 당 가격(원) ÷ 1,000 | G20: SunSirs: Textile Products Industries Bulk Commodity Intelligence | H20: CNY | I20: 기준 : 7월 근접일 (2026-07-27). 시세 지표 : 폴리에스터 장섬유(FDY 150D) 생산자 공시가. 한 생산업체(룽성)의 공시가. 시장 평균 아님
A21: 15 | B21: 운동화 1켤레 · 갑피 : 합성피혁(PU) | C21: 베트남 | D21: 17866.67 | E21: =IF('계산 근거'!J16="","",'계산 근거'!J16) -> 150.76588 | F21: 원료 양 40g (한 켤레 합성피혁 약 40g으로 가정 (가격은 MDI로 대신)) × 1kg 당 가격(원) ÷ 1,000 | G21: 10jqka 폴리우레탄 업종 기사 (iFinD 자료) | H21: CNY | I21: 기준 : 대용 지표 (2026-07-31). 시세 지표 : MDI(폴리우레탄 원료) 중국 현물. 합성피혁 시세가 없어 PU 원료 MDI로 대신함
A22: 16 | B22: 운동화 1켤레 · 안감 : 폴리에스터 원단 | C22: 대만 | D22: 9050 | E22: =IF('계산 근거'!J17="","",'계산 근거'!J17) -> 57.275554 | F22: 원료 양 30g (한 켤레 안감 약 30g으로 가정) × 1kg 당 가격(원) ÷ 1,000 | G22: SunSirs: Textile Products Industries Bulk Commodity Intelligence | H22: CNY | I22: 기준 : 대용 지표 (2026-07-27). 시세 지표 : 폴리에스터 장섬유(FDY 75D) 생산자 공시가. 원단 대신 원사(실) 가격
A23: 17 | B23: 운동화 1켤레 · 깔창 : EVA 수지 | C23: 대한민국 | D23: 10066 | E23: =IF('계산 근거'!J18="","",'계산 근거'!J18) -> 212.35202 | F23: 원료 양 100g (한 켤레 깔창·중창 EVA 약 100g으로 가정) × 1kg 당 가격(원) ÷ 1,000 | G23: SunSirs: China Domestic EVA Market Sees Slight Rise Since Mid-July | H23: CNY | I23: 기준 : 7월 근접일 (2026-07-23). 시세 지표 : EVA 중국 내수 가격. 7월 말 가격은 공개되지 않음
A24: 18 | B24: 운동화 1켤레 · 밑창 : 천연고무 | C24: 태국 | D24: 2155 | E24: =IF('계산 근거'!J19="","",'계산 근거'!J19) -> 138.0924 | F24: 원료 양 45g (밑창 고무 약 150g × 천연고무 30%) × 1kg 당 가격(원) ÷ 1,000 | G24: 瑞达期货 고무 일일 보고서 (2026-07-30) | H24: USD | I24: 기준 : 7월 근접일 (2026-07-30). 시세 지표 : 태국 STR20 현물. 세계은행 7월 평균(TSR20)은 2.14 USD/kg
A25: 19 | B25: 운동화 1켤레 · 밑창 : 합성고무 | C25: 대한민국 | D25: 13300 | E25: =IF('계산 근거'!J20="","",'계산 근거'!J20) -> 294.6052 | F25: 원료 양 105g (밑창 고무 약 150g × 합성고무 70%) × 1kg 당 가격(원) ÷ 1,000 | G25: 瑞达期货 고무 일일 보고서 (2026-07-30) | H25: CNY | I25: 기준 : 7월 근접일 (2026-07-30). 시세 지표 : SBR1502 (중국 치루석화)
B26: 운동화 1켤레 원료 비용 합계 (조사값) | E26: =SUM(E20,E21,E22,E23,E24,E25) -> 964.47776 | F26: 부가가치 학습자료의 원료 단계 금액 : 1,000원 | I26: 조사값 합계를 반올림해 약 1,000원
A27: 20 | B27: 후드 집업 1벌 · 면 (80%) : 면화 | C27: 미국(텍사스주) | D27: 1.96 | E27: =IF('계산 근거'!J21="","",'계산 근거'!J21) -> 1339.6992 | F27: 원료 양 480g (후드 집업(95, M) 약 600g × 면 80%) × 1kg 당 가격(원) ÷ 1,000 | G27: 세계은행 Pink Sheet (2026년 8월 4일 발행, 7월 평균) | H27: USD | I27: 기준 : 7월 평균 (2026년 7월 평균). 시세 지표 : 면화 Cotlook A 지수 (세계은행)
A28: 21 | B28: 후드 집업 1벌 · 폴리에스터 (20%) : 원사 | C28: 중국(저장성) | D28: 7558 | E28: =IF('계산 근거'!J22="","",'계산 근거'!J22) -> 191.33199 | F28: 원료 양 120g (후드 집업 약 600g × 폴리에스터 20%) × 1kg 당 가격(원) ÷ 1,000 | G28: SunSirs: Polyester Staple Fiber Prices Fluctuated Upward in July | H28: CNY | I28: 기준 : 7월 근접일 (2026-07-30). 시세 지표 : 폴리에스터 단섬유(PSF) 중국. 면과 섞는 실은 주로 단섬유
B29: 후드 집업 1벌 원료 비용 합계 (조사값) | E29: =SUM(E27,E28) -> 1531.0312 | F29: 부가가치 학습자료의 원료 단계 금액 : 1,500원 | I29: 조사값 합계를 반올림해 약 1,500원
A30: 22 | B30: 무선 이어폰 1세트 · 배터리 : 리튬(탄산리튬) | C30: 호주, 칠레 | D30: 143350 | E30: =IF('계산 근거'!J23="","",'계산 근거'!J23) -> 39.313391 | F30: 원료 양 1.3g (배터리 약 1.85Wh(500mAh·3.7V), 1kWh당 탄산리튬 약 0.7kg으로 가정) × 1kg 당 가격(원) ÷ 1,000 | G30: CME Battery Metals Market Update (2026-07-31) | H30: CNY | I30: 기준 : 7/31 시세 (2026-07-31). 시세 지표 : 탄산리튬 배터리급 중국 현물. Mysteel 자료를 CME가 인용. SMM 현물은 140,000 CNY/t
A31: 23 | B31: 무선 이어폰 1세트 · 배터리 : 코발트 | C31: 콩고민주공화국 | D31: 26.2 | E31: =IF('계산 근거'!J24="","",'계산 근거'!J24) -> 148.05311 | F31: 원료 양 1.8g (배터리 약 1.85Wh, 1kWh당 코발트 약 1kg으로 가정) × 1kg 당 가격(원) ÷ 1,000 | G31: CME Battery Metals Market Update (2026-07-31) | H31: USD | I31: 기준 : 7/31 시세 (2026-07-31). 시세 지표 : 코발트 표준등급 로테르담 (Fastmarkets). 1파운드 = 0.4536kg으로 환산
A32: 24 | B32: 무선 이어폰 1세트 · 배터리 : 니켈 | C32: 인도네시아 | D32: 17100 | E32: =IF('계산 근거'!J25="","",'계산 근거'!J25) -> 12.1752 | F32: 원료 양 0.5g (전지·도금 부품의 니켈 약 0.5g으로 가정) × 1kg 당 가격(원) ÷ 1,000 | G32: Westmetall LME 니켈 현물 | H32: USD | I32: 기준 : 7/31 시세 (2026-07-31). 시세 지표 : LME 니켈 현물. 세계은행 7월 평균은 16,651 USD/t
A33: 25 | B33: 무선 이어폰 1세트 · 배터리 : 흑연(음극재) | C33: 중국 | E33: =IF('계산 근거'!J26="","",'계산 근거'!J26) | F33: 원료 양 1.85g (배터리 약 1.85Wh, 1kWh당 흑연 약 1kg으로 가정) × 1kg 당 가격(원) ÷ 1,000 | G33: — | H33: — | I33: 기준 : 미확인. 공개된 7월 시세를 찾지 못함(유료 자료)
A34: 26 | B34: 무선 이어폰 1세트 · 외장 : ABS 수지 | C34: 대한민국(여수) | D34: 9616.67 | E34: =IF('계산 근거'!J27="","",'계산 근거'!J27) -> 20.287296 | F34: 원료 양 10g (충전 케이스 외장 약 10g으로 가정) × 1kg 당 가격(원) ÷ 1,000 | G34: SunSirs: China ABS Prices Consolidate After July Rise | H34: CNY | I34: 기준 : 7/31 시세 (2026-07-31). 시세 지표 : ABS 중국 현물 기준가
A35: 27 | B35: 무선 이어폰 1세트 · ABS 원료 : 원유 | C35: 사우디아라비아 | D35: 96.95 | E35: =IF('계산 근거'!J28="","",'계산 근거'!J28) -> 20.242933 | F35: 원료 양 20g (플라스틱 1kg에 원유 약 2kg 가정 → 10g × 2) × 1kg 당 가격(원) ÷ 1,000 · 수지 가격에 이미 들어 있어 합계에서 제외 | G35: 미국 에너지정보청(EIA) Brent 현물 일별 | H35: USD | I35: 기준 : 7/31 시세 (2026-07-31). 시세 지표 : Brent 원유 현물 (EIA)
A36: 28 | B36: 무선 이어폰 1세트 · 외장 : PC 수지 | C36: 대만 | D36: 13983.33 | E36: =IF('계산 근거'!J29="","",'계산 근거'!J29) -> 23.599351 | F36: 원료 양 8g (이어버드 외장 약 8g으로 가정) × 1kg 당 가격(원) ÷ 1,000 | G36: SunSirs: China PC Prices Fell Then Rose in July | H36: CNY | I36: 기준 : 7/31 시세 (2026-07-31). 시세 지표 : PC 중국 현물 기준가
A37: 29 | B37: 무선 이어폰 1세트 · PC 원료 : 원유 | C37: 아랍에미리트 | D37: 96.95 | E37: =IF('계산 근거'!J30="","",'계산 근거'!J30) -> 16.194346 | F37: 원료 양 16g (플라스틱 1kg에 원유 약 2kg 가정 → 8g × 2) × 1kg 당 가격(원) ÷ 1,000 · 수지 가격에 이미 들어 있어 합계에서 제외 | G37: 미국 에너지정보청(EIA) Brent 현물 일별 | H37: USD | I37: 기준 : 7/31 시세 (2026-07-31). 시세 지표 : Brent 원유 현물 (EIA)
A38: 30 | B38: 무선 이어폰 1세트 · 이어팁 : 실리콘 | C38: 중국(둥관) | D38: 12650 | E38: =IF('계산 근거'!J31="","",'계산 근거'!J31) -> 5.3372799 | F38: 원료 양 2g (이어팁 3쌍 약 2g으로 가정) × 1kg 당 가격(원) ÷ 1,000 | G38: SMM Silicone Weekly Review (주간, 7/30까지) | H38: CNY | I38: 기준 : 7월 근접일 (2026-07-30까지 주간). 시세 지표 : 실리콘 원료 DMC 중국 (중간값). 범위 12,500~12,800 CNY/t의 중간값. 완성 실리콘 고무가 아닌 원료 가격
B39: 무선 이어폰 1세트 원료 비용 합계 (조사값) | E39: =SUM(E30,E31,E32,E33,E34,E36,E38) -> 248.76563 | F39: 부가가치 학습자료의 원료 단계 금액 : 300원 | I39: 조사값 합계에 가격을 찾지 못한 흑연 등을 더해 약 300원으로 추정
A40: 31 | B40: 쿠키 1봉(180g) · 밀가루 : 밀 | C40: 미국, 호주 | D40: 310 | E40: =IF('계산 근거'!J32="","",'계산 근거'!J32) -> 27.81072 | F40: 원료 양 63g (쿠키 1봉 180g × 밀가루 약 35%) × 1kg 당 가격(원) ÷ 1,000 | G40: 세계은행 Pink Sheet (2026년 8월 4일 발행, 7월 평균) | H40: USD | I40: 기준 : 7월 평균 (2026년 7월 평균). 시세 지표 : 미국 경질적색겨울밀(HRW) (세계은행)
A41: 32 | B41: 쿠키 1봉(180g) · 코코아매스 : 카카오 | C41: 가나 | D41: 5.61 | E41: =IF('계산 근거'!J33="","",'계산 근거'!J33) -> 115.03642 | F41: 원료 양 14.4g (초콜릿칩 36g × 코코아매스 약 40%) × 1kg 당 가격(원) ÷ 1,000 | G41: 세계은행 Pink Sheet (2026년 8월 4일 발행, 7월 평균) | H41: USD | I41: 기준 : 7월 평균 (2026년 7월 평균). 시세 지표 : 코코아 원두 (세계은행). 원두 가격
...

Sheet 계산 근거
A1: 번호 | B1: 제품 · 원료 | C1: 수출용 도매 가격 (원료 가격 시트) | D1: 통화코드 | E1: 1kg 으로 바꾸는 계수 | F1: 1kg 당 가격 (현지 통화) | G1: 환율 (1단위 = 원) | H1: 1kg 당 가격 (원) | I1: 제품 1단위에 드는 원료 양 (g) | J1: 원료 비용 (원) | K1: 1kg 으로 생산 가능 추정 제품 수
A2: 1 | B2: 립밤 1개 · 시어버터 (35%) | C2: =IF('원료 가격'!D5="","",'원료 가격'!D5) -> 7.24 | D2: USD | E2: 1 | F2: =IF(C2="","",C2*E2) -> 7.24 | G2: =IF(D2="","",INDEX(환율!$C$12:$C$15,MATCH(D2,환율!$A$12:$A$15,0))) -> 1424 | H2: =IF(F2="","",F2*G2) -> 10309.76 | I2: 1.575 | J2: =IF(H2="","",H2*I2/1000) -> 16.237872 | K2: =1000/(I2*1) -> 634.92063
A3: 2 | B3: 립밤 1개 · 밀납 (25%) | C3: =IF('원료 가격'!D6="","",'원료 가격'!D6) -> 9.6 | D3: USD | E3: 1 | F3: =IF(C3="","",C3*E3) -> 9.6 | G3: =IF(D3="","",INDEX(환율!$C$12:$C$15,MATCH(D3,환율!$A$12:$A$15,0))) -> 1424 | H3: =IF(F3="","",F3*G3) -> 13670.4 | I3: 1.125 | J3: =IF(H3="","",H3*I3/1000) -> 15.3792 | K3: =1000/(I3*1) -> 888.88889
A4: 3 | B4: 립밤 1개 · 코코넛오일 (15%) | C4: =IF('원료 가격'!D7="","",'원료 가격'!D7) -> 1924 | D4: USD | E4: 0.001 | F4: =IF(C4="","",C4*E4) -> 1.924 | G4: =IF(D4="","",INDEX(환율!$C$12:$C$15,MATCH(D4,환율!$A$12:$A$15,0))) -> 1424 | H4: =IF(F4="","",F4*G4) -> 2739.776 | I4: 0.675 | J4: =IF(H4="","",H4*I4/1000) -> 1.8493488 | K4: =1000/(I4*1) -> 1481.4815
A5: 4 | B5: 립밤 1개 · 해바라기씨오일 (12%) | C5: =IF('원료 가격'!D8="","",'원료 가격'!D8) -> 1377.5 | D5: USD | E5: 0.001 | F5: =IF(C5="","",C5*E5) -> 1.3775 | G5: =IF(D5="","",INDEX(환율!$C$12:$C$15,MATCH(D5,환율!$A$12:$A$15,0))) -> 1424 | H5: =IF(F5="","",F5*G5) -> 1961.56 | I5: 0.54 | J5: =IF(H5="","",H5*I5/1000) -> 1.0592424 | K5: =1000/(I5*1) -> 1851.8519
A6: 5 | B6: 립밤 1개 · 호호바씨오일 (8%) | C6: =IF('원료 가격'!D9="","",'원료 가격'!D9) -> 14.75 | D6: USD | E6: 1 | F6: =IF(C6="","",C6*E6) -> 14.75 | G6: =IF(D6="","",INDEX(환율!$C$12:$C$15,MATCH(D6,환율!$A$12:$A$15,0))) -> 1424 | H6: =IF(F6="","",F6*G6) -> 21004 | I6: 0.36 | J6: =IF(H6="","",H6*I6/1000) -> 7.56144 | K6: =1000/(I6*1) -> 2777.7778
A7: 6 | B7: 립밤 1개 · 카나우바왁스 (4.5%) | C7: =IF('원료 가격'!D10="","",'원료 가격'!D10) -> 16.4 | D7: USD | E7: 1 | F7: =IF(C7="","",C7*E7) -> 16.4 | G7: =IF(D7="","",INDEX(환율!$C$12:$C$15,MATCH(D7,환율!$A$12:$A$15,0))) -> 1424 | H7: =IF(F7="","",F7*G7) -> 23353.6 | I7: 0.2025 | J7: =IF(H7="","",H7*I7/1000) -> 4.729104 | K7: =1000/(I7*1) -> 4938.2716
A8: 7 | B8: 립밤 1개 · 토코페롤 (0.5%) | C8: =IF('원료 가격'!D11="","",'원료 가격'!D11) | F8: =IF(C8="","",C8*E8) | G8: =IF(D8="","",INDEX(환율!$C$12:$C$15,MATCH(D8,환율!$A$12:$A$15,0))) | H8: =IF(F8="","",F8*G8) | I8: 0.0225 | J8: =IF(H8="","",H8*I8/1000) | K8: =1000/(I8*1) -> 44444.444
A9: 8 | B9: 립밤 1개 · 용기 : 폴리프로필렌(PP) 수지 | C9: =IF('원료 가격'!D12="","",'원료 가격'!D12) -> 8973.33 | D9: CNY | E9: 0.001 | F9: =IF(C9="","",C9*E9) -> 8.97333 | G9: =IF(D9="","",INDEX(환율!$C$12:$C$15,MATCH(D9,환율!$A$12:$A$15,0))) -> 210.95968 | H9: =IF(F9="","",F9*G9) -> 1893.0108 | I9: 5 | J9: =IF(H9="","",H9*I9/1000) -> 9.4650542 | K9: =1000/(I9*1) -> 200
A10: 9 | B10: 립밤 1개 · 용기 : 수지 원료(원유) | C10: =IF('원료 가격'!D13="","",'원료 가격'!D13) -> 96.95 | D10: USD | E10: =1/136.4 -> 0.0073313783 | F10: =IF(C10="","",C10*E10) -> 0.71077713 | G10: =IF(D10="","",INDEX(환율!$C$12:$C$15,MATCH(D10,환율!$A$12:$A$15,0))) -> 1424 | H10: =IF(F10="","",F10*G10) -> 1012.1466 | I10: 10 | J10: =IF(H10="","",H10*I10/1000) -> 10.121466 | K10: =1000/(I10*1) -> 100
A11: 10 | B11: 사인펜 1상자(12자루) · 몸체·캡 : PP 수지 | C11: =IF('원료 가격'!D15="","",'원료 가격'!D15) -> 8973.33 | D11: CNY | E11: 0.001 | F11: =IF(C11="","",C11*E11) -> 8.97333 | G11: =IF(D11="","",INDEX(환율!$C$12:$C$15,MATCH(D11,환율!$A$12:$A$15,0))) -> 210.95968 | H11: =IF(F11="","",F11*G11) -> 1893.0108 | I11: 60 | J11: =IF(H11="","",H11*I11/1000) -> 113.58065 | K11: =1000/(I11*1) -> 16.666667
A12: 11 | B12: 사인펜 1상자(12자루) · PP 원료 : 원유 | C12: =IF('원료 가격'!D16="","",'원료 가격'!D16) -> 96.95 | D12: USD | E12: =1/136.4 -> 0.0073313783 | F12: =IF(C12="","",C12*E12) -> 0.71077713 | G12: =IF(D12="","",INDEX(환율!$C$12:$C$15,MATCH(D12,환율!$A$12:$A$15,0))) -> 1424 | H12: =IF(F12="","",F12*G12) -> 1012.1466 | I12: 120 | J12: =IF(H12="","",H12*I12/1000) -> 121.4576 | K12: =1000/(I12*1) -> 8.3333333
A13: 12 | B13: 사인펜 1상자(12자루) · 펜촉 : 폴리에스터 섬유 | C13: =IF('원료 가격'!D17="","",'원료 가격'!D17) -> 7558 | D13: CNY | E13: 0.001 | F13: =IF(C13="","",C13*E13) -> 7.558 | G13: =IF(D13="","",INDEX(환율!$C$12:$C$15,MATCH(D13,환율!$A$12:$A$15,0))) -> 210.95968 | H13: =IF(F13="","",F13*G13) -> 1594.4333 | I13: 1.2 | J13: =IF(H13="","",H13*I13/1000) -> 1.9133199 | K13: =1000/(I13*1) -> 833.33333
A14: 13 | B14: 사인펜 1상자(12자루) · 잉크 : 카본블랙 안료 | C14: =IF('원료 가격'!D18="","",'원료 가격'!D18) | F14: =IF(C14="","",C14*E14) | G14: =IF(D14="","",INDEX(환율!$C$12:$C$15,MATCH(D14,환율!$A$12:$A$15,0))) | H14: =IF(F14="","",F14*G14) | I14: 0.9 | J14: =IF(H14="","",H14*I14/1000) | K14: =1000/(I14*1) -> 1111.1111
A15: 14 | B15: 운동화 1켤레 · 갑피 : 폴리에스터 원사 | C15: =IF('원료 가격'!D20="","",'원료 가격'!D20) -> 8800 | D15: CNY | E15: 0.001 | F15: =IF(C15="","",C15*E15) -> 8.8 | G15: =IF(D15="","",INDEX(환율!$C$12:$C$15,MATCH(D15,환율!$A$12:$A$15,0))) -> 210.95968 | H15: =IF(F15="","",F15*G15) -> 1856.4452 | I15: 60 | J15: =IF(H15="","",H15*I15/1000) -> 111.38671 | K15: =1000/(I15*1) -> 16.666667
A16: 15 | B16: 운동화 1켤레 · 갑피 : 합성피혁(PU) | C16: =IF('원료 가격'!D21="","",'원료 가격'!D21) -> 17866.67 | D16: CNY | E16: 0.001 | F16: =IF(C16="","",C16*E16) -> 17.86667 | G16: =IF(D16="","",INDEX(환율!$C$12:$C$15,MATCH(D16,환율!$A$12:$A$15,0))) -> 210.95968 | H16: =IF(F16="","",F16*G16) -> 3769.147 | I16: 40 | J16: =IF(H16="","",H16*I16/1000) -> 150.76588 | K16: =1000/(I16*1) -> 25
A17: 16 | B17: 운동화 1켤레 · 안감 : 폴리에스터 원단 | C17: =IF('원료 가격'!D22="","",'원료 가격'!D22) -> 9050 | D17: CNY | E17: 0.001 | F17: =IF(C17="","",C17*E17) -> 9.05 | G17: =IF(D17="","",INDEX(환율!$C$12:$C$15,MATCH(D17,환율!$A$12:$A$15,0))) -> 210.95968 | H17: =IF(F17="","",F17*G17) -> 1909.1851 | I17: 30 | J17: =IF(H17="","",H17*I17/1000) -> 57.275554 | K17: =1000/(I17*1) -> 33.333333
A18: 17 | B18: 운동화 1켤레 · 깔창 : EVA 수지 | C18: =IF('원료 가격'!D23="","",'원료 가격'!D23) -> 10066 | D18: CNY | E18: 0.001 | F18: =IF(C18="","",C18*E18) -> 10.066 | G18: =IF(D18="","",INDEX(환율!$C$12:$C$15,MATCH(D18,환율!$A$12:$A$15,0))) -> 210.95968 | H18: =IF(F18="","",F18*G18) -> 2123.5202 | I18: 100 | J18: =IF(H18="","",H18*I18/1000) -> 212.35202 | K18: =1000/(I18*1) -> 10
A19: 18 | B19: 운동화 1켤레 · 밑창 : 천연고무 | C19: =IF('원료 가격'!D24="","",'원료 가격'!D24) -> 2155 | D19: USD | E19: 0.001 | F19: =IF(C19="","",C19*E19) -> 2.155 | G19: =IF(D19="","",INDEX(환율!$C$12:$C$15,MATCH(D19,환율!$A$12:$A$15,0))) -> 1424 | H19: =IF(F19="","",F19*G19) -> 3068.72 | I19: 45 | J19: =IF(H19="","",H19*I19/1000) -> 138.0924 | K19: =1000/(I19*1) -> 22.222222
A20: 19 | B20: 운동화 1켤레 · 밑창 : 합성고무 | C20: =IF('원료 가격'!D25="","",'원료 가격'!D25) -> 13300 | D20: CNY | E20: 0.001 | F20: =IF(C20="","",C20*E20) -> 13.3 | G20: =IF(D20="","",INDEX(환율!$C$12:$C$15,MATCH(D20,환율!$A$12:$A$15,0))) -> 210.95968 | H20: =IF(F20="","",F20*G20) -> 2805.7638 | I20: 105 | J20: =IF(H20="","",H20*I20/1000) -> 294.6052 | K20: =1000/(I20*1) -> 9.5238095
A21: 20 | B21: 후드 집업 1벌 · 면 (80%) : 면화 | C21: =IF('원료 가격'!D27="","",'원료 가격'!D27) -> 1.96 | D21: USD | E21: 1 | F21: =IF(C21="","",C21*E21) -> 1.96 | G21: =IF(D21="","",INDEX(환율!$C$12:$C$15,MATCH(D21,환율!$A$12:$A$15,0))) -> 1424 | H21: =IF(F21="","",F21*G21) -> 2791.04 | I21: 480 | J21: =IF(H21="","",H21*I21/1000) -> 1339.6992 | K21: =1000/(I21*1) -> 2.0833333
A22: 21 | B22: 후드 집업 1벌 · 폴리에스터 (20%) : 원사 | C22: =IF('원료 가격'!D28="","",'원료 가격'!D28) -> 7558 | D22: CNY | E22: 0.001 | F22: =IF(C22="","",C22*E22) -> 7.558 | G22: =IF(D22="","",INDEX(환율!$C$12:$C$15,MATCH(D22,환율!$A$12:$A$15,0))) -> 210.95968 | H22: =IF(F22="","",F22*G22) -> 1594.4333 | I22: 120 | J22: =IF(H22="","",H22*I22/1000) -> 191.33199 | K22: =1000/(I22*1) -> 8.3333333
A23: 22 | B23: 무선 이어폰 1세트 · 배터리 : 리튬(탄산리튬) | C23: =IF('원료 가격'!D30="","",'원료 가격'!D30) -> 143350 | D23: CNY | E23: 0.001 | F23: =IF(C23="","",C23*E23) -> 143.35 | G23: =IF(D23="","",INDEX(환율!$C$12:$C$15,MATCH(D23,환율!$A$12:$A$15,0))) -> 210.95968 | H23: =IF(F23="","",F23*G23) -> 30241.07 | I23: 1.3 | J23: =IF(H23="","",H23*I23/1000) -> 39.313391 | K23: =1000/(I23*1) -> 769.23077
A24: 23 | B24: 무선 이어폰 1세트 · 배터리 : 코발트 | C24: =IF('원료 가격'!D31="","",'원료 가격'!D31) -> 26.2 | D24: USD | E24: 2.20462 | F24: =IF(C24="","",C24*E24) -> 57.761044 | G24: =IF(D24="","",INDEX(환율!$C$12:$C$15,MATCH(D24,환율!$A$12:$A$15,0))) -> 1424 | H24: =IF(F24="","",F24*G24) -> 82251.727 | I24: 1.8 | J24: =IF(H24="","",H24*I24/1000) -> 148.05311 | K24: =1000/(I24*1) -> 555.55556
A25: 24 | B25: 무선 이어폰 1세트 · 배터리 : 니켈 | C25: =IF('원료 가격'!D32="","",'원료 가격'!D32) -> 17100 | D25: USD | E25: 0.001 | F25: =IF(C25="","",C25*E25) -> 17.1 | G25: =IF(D25="","",INDEX(환율!$C$12:$C$15,MATCH(D25,환율!$A$12:$A$15,0))) -> 1424 | H25: =IF(F25="","",F25*G25) -> 24350.4 | I25: 0.5 | J25: =IF(H25="","",H25*I25/1000) -> 12.1752 | K25: =1000/(I25*1) -> 2000
A26: 25 | B26: 무선 이어폰 1세트 · 배터리 : 흑연(음극재) | C26: =IF('원료 가격'!D33="","",'원료 가격'!D33) | F26: =IF(C26="","",C26*E26) | G26: =IF(D26="","",INDEX(환율!$C$12:$C$15,MATCH(D26,환율!$A$12:$A$15,0))) | H26: =IF(F26="","",F26*G26) | I26: 1.85 | J26: =IF(H26="","",H26*I26/1000) | K26: =1000/(I26*1) -> 540.54054
A27: 26 | B27: 무선 이어폰 1세트 · 외장 : ABS 수지 | C27: =IF('원료 가격'!D34="","",'원료 가격'!D34) -> 9616.67 | D27: CNY | E27: 0.001 | F27: =IF(C27="","",C27*E27) -> 9.61667 | G27: =IF(D27="","",INDEX(환율!$C$12:$C$15,MATCH(D27,환율!$A$12:$A$15,0))) -> 210.95968 | H27: =IF(F27="","",F27*G27) -> 2028.7296 | I27: 10 | J27: =IF(H27="","",H27*I27/1000) -> 20.287296 | K27: =1000/(I27*1) -> 100
A28: 27 | B28: 무선 이어폰 1세트 · ABS 원료 : 원유 | C28: =IF('원료 가격'!D35="","",'원료 가격'!D35) -> 96.95 | D28: USD | E28: =1/136.4 -> 0.0073313783 | F28: =IF(C28="","",C28*E28) -> 0.71077713 | G28: =IF(D28="","",INDEX(환율!$C$12:$C$15,MATCH(D28,환율!$A$12:$A$15,0))) -> 1424 | H28: =IF(F28="","",F28*G28) -> 1012.1466 | I28: 20 | J28: =IF(H28="","",H28*I28/1000) -> 20.242933 | K28: =1000/(I28*1) -> 50
A29: 28 | B29: 무선 이어폰 1세트 · 외장 : PC 수지 | C29: =IF('원료 가격'!D36="","",'원료 가격'!D36) -> 13983.33 | D29: CNY | E29: 0.001 | F29: =IF(C29="","",C29*E29) -> 13.98333 | G29: =IF(D29="","",INDEX(환율!$C$12:$C$15,MATCH(D29,환율!$A$12:$A$15,0))) -> 210.95968 | H29: =IF(F29="","",F29*G29) -> 2949.9188 | I29: 8 | J29: =IF(H29="","",H29*I29/1000) -> 23.599351 | K29: =1000/(I29*1) -> 125
A30: 29 | B30: 무선 이어폰 1세트 · PC 원료 : 원유 | C30: =IF('원료 가격'!D37="","",'원료 가격'!D37) -> 96.95 | D30: USD | E30: =1/136.4 -> 0.0073313783 | F30: =IF(C30="","",C30*E30) -> 0.71077713 | G30: =IF(D30="","",INDEX(환율!$C$12:$C$15,MATCH(D30,환율!$A$12:$A$15,0))) -> 1424 | H30: =IF(F30="","",F30*G30) -> 1012.1466 | I30: 16 | J30: =IF(H30="","",H30*I30/1000) -> 16.194346 | K30: =1000/(I30*1) -> 62.5
A31: 30 | B31: 무선 이어폰 1세트 · 이어팁 : 실리콘 | C31: =IF('원료 가격'!D38="","",'원료 가격'!D38) -> 12650 | D31: CNY | E31: 0.001 | F31: =IF(C31="","",C31*E31) -> 12.65 | G31: =IF(D31="","",INDEX(환율!$C$12:$C$15,MATCH(D31,환율!$A$12:$A$15,0))) -> 210.95968 | H31: =IF(F31="","",F31*G31) -> 2668.64 | I31: 2 | J31: =IF(H31="","",H31*I31/1000) -> 5.3372799 | K31: =1000/(I31*1) -> 500
A32: 31 | B32: 쿠키 1봉(180g) · 밀가루 : 밀 | C32: =IF('원료 가격'!D40="","",'원료 가격'!D40) -> 310 | D32: USD | E32: 0.001 | F32: =IF(C32="","",C32*E32) -> 0.31 | G32: =IF(D32="","",INDEX(환율!$C$12:$C$15,MATCH(D32,환율!$A$12:$A$15,0))) -> 1424 | H32: =IF(F32="","",F32*G32) -> 441.44 | I32: 63 | J32: =IF(H32="","",H32*I32/1000) -> 27.81072 | K32: =1000/(I32*12) -> 1.3227513
A33: 32 | B33: 쿠키 1봉(180g) · 코코아매스 : 카카오 | C33: =IF('원료 가격'!D41="","",'원료 가격'!D41) -> 5.61 | D33: USD | E33: 1 | F33: =IF(C33="","",C33*E33) -> 5.61 | G33: =IF(D33="","",INDEX(환율!$C$12:$C$15,MATCH(D33,환율!$A$12:$A$15,0))) -> 1424 | H33: =IF(F33="","",F33*G33) -> 7988.64 | I33: 14.4 | J33: =IF(H33="","",H33*I33/1000) -> 115.03642 | K33: =1000/(I33*12) -> 5.787037
A34: 33 | B34: 쿠키 1봉(180g) · 코코아버터 : 카카오 | C34: =IF('원료 가격'!D42="","",'원료 가격'!D42) -> 5.61 | D34: USD | E34: 1 | F34: =IF(C34="","",C34*E34) -> 5.61 | G34: =IF(D34="","",INDEX(환율!$C$12:$C$15,MATCH(D34,환율!$A$12:$A$15,0))) -> 1424 | H34: =IF(F34="","",F34*G34) -> 7988.64 | I34: 5.4 | J34: =IF(H34="","",H34*I34/1000) -> 43.138656 | K34: =1000/(I34*12) -> 15.432099
A35: 34 | B35: 쿠키 1봉(180g) · 코코아분말 | C35: =IF('원료 가격'!D43="","",'원료 가격'!D43) -> 5.61 | D35: USD | E35: 1 | F35: =IF(C35="","",C35*E35) -> 5.61 | G35: =IF(D35="","",INDEX(환율!$C$12:$C$15,MATCH(D35,환율!$A$12:$A$15,0))) -> 1424 | H35: =IF(F35="","",F35*G35) -> 7988.64 | I35: 5.4 | J35: =IF(H35="","",H35*I35/1000) -> 43.138656 | K35: =1000/(I35*12) -> 15.432099
A36: 35 | B36: 쿠키 1봉(180g) · 설탕 : 원당 | C36: =IF('원료 가격'!D44="","",'원료 가격'!D44) -> 0.34 | D36: USD | E36: 1 | F36: =IF(C36="","",C36*E36) -> 0.34 | G36: =IF(D36="","",INDEX(환율!$C$12:$C$15,MATCH(D36,환율!$A$12:$A$15,0))) -> 1424 | H36: =IF(F36="","",F36*G36) -> 484.16 | I36: 36 | J36: =IF(H36="","",H36*I36/1000) -> 17.42976 | K36: =1000/(I36*12) -> 2.3148148
A37: 36 | B37: 쿠키 1봉(180g) · 초콜릿칩 속 설탕 | C37: =IF('원료 가격'!D45="","",'원료 가격'!D45) -> 0.34 | D37: USD | E37: 1 | F37: =IF(C37="","",C37*E37) -> 0.34 | G37: =IF(D37="","",INDEX(환율!$C$12:$C$15,MATCH(D37,환율!$A$12:$A$15,0))) -> 1424 | H37: =IF(F37="","",F37*G37) -> 484.16 | I37: 16.2 | J37: =IF(H37="","",H37*I37/1000) -> 7.843392 | K37: =1000/(I37*12) -> 5.1440329
A38: 37 | B38: 쿠키 1봉(180g) · 버터 : 우유 | C38: =IF('원료 가격'!D46="","",'원료 가격'!D46) -> 3960 | D38: EUR | E38: 0.001 | F38: =IF(C38="","",C38*E38) -> 3.96 | G38: =IF(D38="","",INDEX(환율!$C$12:$C$15,MATCH(D38,환율!$A$12:$A$15,0))) -> 1640.1872 | H38: =IF(F38="","",F38*G38) -> 6495.1411 | I38: 32.4 | J38: =IF(H38="","",H38*I38/1000) -> 210.44257 | K38: =1000/(I38*12) -> 2.5720165
A39: 38 | B39: 쿠키 1봉(180g) · 팜유 | C39: =IF('원료 가격'!D47="","",'원료 가격'!D47) -> 1101 | D39: USD | E39: 0.001 | F39: =IF(C39="","",C39*E39) -> 1.101 | G39: =IF(D39="","",INDEX(환율!$C$12:$C$15,MATCH(D39,환율!$A$12:$A$15,0))) -> 1424 | H39: =IF(F39="","",F39*G39) -> 1567.824 | I39: 14.4 | J39: =IF(H39="","",H39*I39/1000) -> 22.576666 | K39: =1000/(I39*12) -> 5.787037
A40: 39 | B40: 쿠키 1봉(180g) · 계란 | C40: =IF('원료 가격'!D48="","",'원료 가격'!D48) -> 2256 | D40: KRW | E40: =1/0.64 -> 1.5625 | F40: =IF(C40="","",C40*E40) -> 3525 | G40: =IF(D40="","",INDEX(환율!$C$12:$C$15,MATCH(D40,환율!$A$12:$A$15,0))) -> 1 | H40: =IF(F40="","",F40*G40) -> 3525 | I40: 14.4 | J40: =IF(H40="","",H40*I40/1000) -> 50.76 | K40: =1000/(I40*12) -> 5.787037
...

Sheet 환율
A1: 환율 — 2026년 7월 31일(금)
A2: 입력값 (파란 글씨)
A3: 원/달러 (서울외환시장 종가) | B3: 1424 | C3: 원 | D3: 머니투데이 2026-07-31 「원/달러 환율, 13.4원 내린 1424.0원」 | E3: https://www.mt.co.kr/economy/2026/07/31/2026073115373095223
A4: 엔/달러 (MUFG 매도율 TTS) | B4: 161.72 | C4: 엔 | D4: MUFG 미쓰비시UFJ 2026-07-31 외환시세 | E4: https://murc-kawasesouba.jp/fx/past/index.php?id=260731
A5: 엔/달러 (MUFG 매입률 TTB) | B5: 159.72 | C5: 엔 | D5: 〃
A6: 엔/위안 (MUFG TTS) | B6: 24.11 | C6: 엔 | D6: 〃 (역외 위안 기준)
A7: 엔/위안 (MUFG TTB) | B7: 23.51 | C7: 엔 | D7: 〃
A8: 엔/유로 (MUFG TTS) | B8: 186.62 | C8: 엔 | D8: 〃
A9: 엔/유로 (MUFG TTB) | B9: 183.62 | C9: 엔 | D9: 〃
A11: 통화코드 | B11: 계산 방법 | C11: 1단위 = 원
A12: USD | B12: 달러 : 서울 종가 그대로 | C12: =B3 -> 1424
A13: CNY | B13: 위안 : 원/달러 ÷ (엔/달러 중간값 ÷ 엔/위안 중간값) | C13: =B3/((B4+B5)/2/((B6+B7)/2)) -> 210.95968
A14: EUR | B14: 유로 : 원/달러 × (엔/유로 중간값 ÷ 엔/달러 중간값) | C14: =B3*((B8+B9)/2/((B4+B5)/2)) -> 1640.1872
A15: KRW | B15: 원화 | C15: 1
A17: ※ 위안·유로 환율은 같은 날 일본 MUFG 고시 환율로 달러와의 교차환율을 구해 원화로 바꾼 값입니다.
